## Java异常处理

### Java的异常

一个健壮的程序必须处理各种各样的错误。所谓错误，就是程序调用某个函数的时候，如果失败了，就表示出错。

调用方如何获知调用失败的信息？有两种方法：

#### 方法一：约定返回错误码。

例如，处理一个文件，如果返回`0`，表示成功，返回其他整数，表示约定的错误码：

```java
int code = processFile("C:\\test.txt");
if (code == 0) {
    // ok:
} else {
    // error:
    switch (code) {
    case 1:
        // file not found:
    case 2:
        // no read permission:
    default:
        // unknown error:
    }
}
```

因为使用`int`类型的错误码，想要处理就非常麻烦。这种方式常见于底层C函数。

#### 方法二：在语言层面上提供一个异常处理机制。

Java内置了一套异常处理机制，总是使用异常来表示错误。

异常是一种`class`，因此它本身带有类型信息。异常可以在任何地方抛出，但只需要在上层捕获，这样就和方法调用分离了：

```java
try {
    String s = processFile(“C:\\test.txt”);
    // ok:
} catch (FileNotFoundException e) {
    // file not found:
} catch (SecurityException e) {
    // no read permission:
} catch (IOException e) {
    // io error:
} catch (Exception e) {
    // other error:
}
```

因为Java的异常是`class`，它的继承关系如下：

![image-20220403144231308](https://gitee.com/wmbyy/typora_pictures/raw/master/pictures/image-20220403144231308.png)

从继承关系可知：`Throwable`是异常体系的根，它继承自`Object`。`Throwable`有两个体系：`Error`和`Exception`，`Error`表示严重的错误，程序对此一般无能为力，例如：

- `OutOfMemoryError`：内存耗尽
- `NoClassDefFoundError`：无法加载某个Class
- `StackOverflowError`：栈溢出

而`Exception`则是运行时的错误，它可以被捕获并处理。

某些异常是应用程序逻辑处理的一部分，应该捕获并处理。例如：

- `NumberFormatException`：数值类型的格式错误
- `FileNotFoundException`：未找到文件
- `SocketException`：读取网络失败

还有一些异常是程序逻辑编写不对造成的，应该修复程序本身。例如：

- `NullPointerException`：对某个`null`的对象调用方法或字段
- `IndexOutOfBoundsException`：数组索引越界

`Exception`又分为两大类：

1. `RuntimeException`以及它的子类；
2. 非`RuntimeException`（包括`IOException`、`ReflectiveOperationException`等等）

Java规定：

- 必须捕获的异常，包括`Exception`及其子类，但不包括`RuntimeException`及其子类，这种类型的异常称为Checked Exception。
- 不需要捕获的异常，包括`Error`及其子类，`RuntimeException`及其子类。

**注意：编译器对RuntimeException及其子类不做强制捕获要求，不是指应用程序本身不应该捕获并处理RuntimeException。是否需要捕获，具体问题具体分析。**

#### 捕获异常

捕获异常使用`try...catch`语句，把可能发生异常的代码放到`try {...}`中，然后使用`catch`捕获对应的`Exception`及其子类：

```java
public class Main {
    public static void main(String[] args) {
        byte[] bs = toGBK("中文");
        System.out.println(Arrays.toString(bs));
    }

    static byte[] toGBK(String s) {
        try {
            // 用指定编码转换String为byte[]:
            return s.getBytes("GBK");
        } catch (UnsupportedEncodingException e) {
            // 如果系统不支持GBK编码，会捕获到UnsupportedEncodingException:
            System.out.println(e); // 打印异常信息
            return s.getBytes(); // 尝试使用用默认编码
        }
    }
}
```

如果我们不捕获`UnsupportedEncodingException`，会出现编译失败的问题：

```java
public class Main {
    public static void main(String[] args) {
        byte[] bs = toGBK("中文");
        System.out.println(Arrays.toString(bs));
    }

    static byte[] toGBK(String s) {
        return s.getBytes("GBK");
    }
}
#出现：java: 未报告的异常错误java.io.UnsupportedEncodingException; 必须对其进行捕获或声明以便抛出
```

这是因为`String.getBytes(String)`方法定义是：

```java
public byte[] getBytes(String charsetName) throws UnsupportedEncodingException {
    ...
}
```

在方法定义的时候，使用`throws Xxx`表示该方法可能抛出的异常类型。调用方在调用的时候，必须强制捕获这些异常，否则编译器会报错。

我们也可以不捕获它，而是在方法定义处用throws表示`toGBK()`方法可能会抛出`UnsupportedEncodingException`，就可以让`toGBK()`方法通过编译器检查：

```java
public class Main {
    public static void main(String[] args) {
        byte[] bs = toGBK("中文");
        System.out.println(Arrays.toString(bs));
    }

    static byte[] toGBK(String s) throws UnsupportedEncodingException {
        return s.getBytes("GBK");
    }
}
```

上述代码仍然会得到编译错误，但这一次，编译器提示的不是调用`return s.getBytes("GBK");`的问题，而是`byte[] bs = toGBK("中文");`。因为在`main()`方法中，调用`toGBK()`，没有捕获它声明的可能抛出的`UnsupportedEncodingException`。

修复方法是在`main()`方法中捕获异常并处理：

```java
public class Main {
    public static void main(String[] args) {
        try {
            byte[] bs = toGBK("中文");
            System.out.println(Arrays.toString(bs));
        } catch (UnsupportedEncodingException e) {
            System.out.println(e);
        }
    }

    static byte[] toGBK(String s) throws UnsupportedEncodingException {
        // 用指定编码转换String为byte[]:
        return s.getBytes("GBK");
    }
}
```

可见，只要是方法声明的Checked Exception，不在调用层捕获，也必须在更高的调用层捕获。所有未捕获的异常，最终也必须在`main()`方法中捕获，不会出现漏写`try`的情况。这是由编译器保证的。`main()`方法也是最后捕获`Exception`的机会。

如果是测试代码，上面的写法就略显麻烦。如果不想写任何`try`代码，可以直接把`main()`方法定义为`throws Exception`：

```java
public class Main {
    public static void main(String[] args) throws Exception {
        byte[] bs = toGBK("中文");
        System.out.println(Arrays.toString(bs));
    }

    static byte[] toGBK(String s) throws UnsupportedEncodingException {
        // 用指定编码转换String为byte[]:
        return s.getBytes("GBK");
    }
}
```

因为`main()`方法声明了可能抛出`Exception`，也就声明了可能抛出所有的`Exception`，因此在内部就无需捕获了。代价就是一旦发生异常，程序会立刻退出。

还有一些童鞋喜欢在`toGBK()`内部“消化”异常：

```java
static byte[] toGBK(String s) {
    try {
        return s.getBytes("GBK");
    } catch (UnsupportedEncodingException e) {
        // 什么也不干
    }
    return null;
```

这种捕获后不处理的方式是非常不好的，即使真的什么也做不了，也要先把异常记录下来：

```java
static byte[] toGBK(String s) {
    try {
        return s.getBytes("GBK");
    } catch (UnsupportedEncodingException e) {
        // 先记下来再说:
        e.printStackTrace();
    }
    return null;
```

所有异常都可以调用`printStackTrace()`方法打印异常栈，这是一个简单有用的快速打印异常的方法。

#### 小结

Java使用异常来表示错误，并通过`try ... catch`捕获异常；

Java的异常是`class`，并且从`Throwable`继承；

`Error`是无需捕获的严重错误，`Exception`是应该捕获的可处理的错误；

`RuntimeException`无需强制捕获，非`RuntimeException`（Checked Exception）需强制捕获，或者用`throws`声明；

不推荐捕获了异常但不进行任何处理。

### 捕获异常

在Java中，凡是可能抛出异常的语句，都可以用`try ... catch`捕获。把可能发生异常的语句放在`try { ... }`中，然后使用`catch`捕获对应的`Exception`及其子类。

#### 多catch语句

可以使用多个`catch`语句，每个`catch`分别捕获对应的`Exception`及其子类。JVM在捕获到异常后，会从上到下匹配`catch`语句，匹配到某个`catch`后，执行`catch`代码块，然后*不再*继续匹配。

简单地说就是：多个`catch`语句只有一个能被执行。例如：

```java
public static void main(String[] args) {
    try {
        process1();
        process2();
        process3();
    } catch (IOException e) {
        System.out.println(e);
    } catch (NumberFormatException e) {
        System.out.println(e);
    }
}
```

存在多个`catch`的时候，`catch`的顺序非常重要：子类必须写在前面。例如：

```java
public static void main(String[] args) {
    try {
        process1();
        process2();
        process3();
    } catch (IOException e) {
        System.out.println("IO error");
    } catch (UnsupportedEncodingException e) { // 永远捕获不到
        System.out.println("Bad encoding");
    }
}
```

对于上面的代码，`UnsupportedEncodingException`异常是永远捕获不到的，因为它是`IOException`的子类。当抛出`UnsupportedEncodingException`异常时，会被`catch (IOException e) { ... }`捕获并执行。

#### finally语句

无论是否有异常发生，如果我们都希望执行一些语句，例如清理工作，怎么写？

可以把执行语句写若干遍：正常执行的放到`try`中，每个`catch`再写一遍。例如：

```java
public static void main(String[] args) {
    try {
        process1();
        process2();
        process3();
        System.out.println("END");
    } catch (UnsupportedEncodingException e) {
        System.out.println("Bad encoding");
        System.out.println("END");
    } catch (IOException e) {
        System.out.println("IO error");
        System.out.println("END");
    }
}
```

上述代码无论是否发生异常，都会执行`System.out.println("END");`这条语句。

那么如何消除这些重复的代码？Java的`try ... catch`机制还提供了`finally`语句，`finally`语句块保证有无错误都会执行。上述代码可以改写如下：

```java
public static void main(String[] args) {
    try {
        process1();
        process2();
        process3();
    } catch (UnsupportedEncodingException e) {
        System.out.println("Bad encoding");
    } catch (IOException e) {
        System.out.println("IO error");
    } finally {
        System.out.println("END");
    }
}
```

注意`finally`有几个特点：

1. `finally`语句不是必须的，可写可不写；
2. `finally`总是最后执行。

如果没有发生异常，就正常执行`try { ... }`语句块，然后执行`finally`。如果发生了异常，就中断执行`try { ... }`语句块，然后跳转执行匹配的`catch`语句块，最后执行`finally`。

可见，`finally`是用来保证一些代码必须执行的。

某些情况下，可以没有`catch`，只使用`try ... finally`结构。例如：

```java
void process(String file) throws IOException {
    try {
        ...
    } finally {
        System.out.println("END");
    }
}
```

因为方法声明了可能抛出的异常，所以可以不写`catch`。

#### 捕获多种异常

如果某些异常的处理逻辑相同，但是异常本身不存在继承关系，那么就得编写多条`catch`子句：

```java
public static void main(String[] args) {
    try {
        process1();
        process2();
        process3();
    } catch (IOException e) {
        System.out.println("Bad input");
    } catch (NumberFormatException e) {
        System.out.println("Bad input");
    } catch (Exception e) {
        System.out.println("Unknown error");
    }
}
```

因为处理`IOException`和`NumberFormatException`的代码是相同的，所以我们可以把它两用`|`合并到一起：

```java
public static void main(String[] args) {
    try {
        process1();
        process2();
        process3();
    } catch (IOException | NumberFormatException e) { // IOException或NumberFormatException
        System.out.println("Bad input");
    } catch (Exception e) {
        System.out.println("Unknown error");
    }
}
```

#### 小结

使用`try ... catch ... finally`时：

- 多个`catch`语句的匹配顺序非常重要，子类必须放在前面；
- `finally`语句保证了有无异常都会执行，它是可选的；
- 一个`catch`语句也可以匹配多个非继承关系的异常。

### **抛出异常**

#### 异常的传播

当某个方法抛出了异常时，如果当前方法没有捕获异常，异常就会被抛到上层调用方法，直到遇到某个`try ... catch`被捕获为止：

```java
public class Main {
    public static void main(String[] args) {
        try {
            process1();
        } catch (Exception e) {
            e.printStackTrace();
        }
    }

    static void process1() {
        process2();
    }

    static void process2() {
        Integer.parseInt(null); // 会抛出NumberFormatException
    }
}
```

通过`printStackTrace()`可以打印出方法的调用栈，类似：

```java
java.lang.NumberFormatException: null
	at java.lang.Integer.parseInt(Integer.java:542)
	at java.lang.Integer.parseInt(Integer.java:615)
	at com.ln.exception.Main.process2(Main.java:20)
	at com.ln.exception.Main.process1(Main.java:16)
	at com.ln.exception.Main.main(Main.java:9)
```

`printStackTrace()`对于调试错误非常有用，上述信息表示：`NumberFormatException`是在`java.lang.Integer.parseInt`方法中被抛出的，从下往上看，调用层次依次是：

1. `main()`调用`process1()`；
2. `process1()`调用`process2()`；
3. `process2()`调用`Integer.parseInt(String)`；
4. `Integer.parseInt(String)`调用`Integer.parseInt(String, int)`。

查看`Integer.java`源码可知，抛出异常的方法代码如下：

```java
public static int parseInt(String s, int radix) throws NumberFormatException {
    if (s == null) {
        throw new NumberFormatException("null");
    }
    ...
}
```

并且，每层调用均给出了源代码的行号，可直接定位。

#### 抛出异常

当发生错误时，例如，用户输入了非法的字符，我们就可以抛出异常。

如何抛出异常？参考`Integer.parseInt()`方法，抛出异常分两步：

1. 创建某个`Exception`的实例；
2. 用`throw`语句抛出。

下面是一个例子：

```java
void process2(String s) {
    if (s==null) {
        NullPointerException e = new NullPointerException();
        throw e;
    }
}
```

实际上，绝大部分抛出异常的代码都会合并写成一行：

```java
void process2(String s) {
    if (s==null) {
        throw new NullPointerException();
    }
}
```

如果一个方法捕获了某个异常后，又在`catch`子句中抛出新的异常，就相当于把抛出的异常类型“转换”了：

```java
void process1(String s) {
    try {
        process2();
    } catch (NullPointerException e) {
        throw new IllegalArgumentException();
    }
}

void process2(String s) {
    if (s==null) {
        throw new NullPointerException();
    }
}
// 所以Spring的异常转换体系就是这么干的
```

当`process2()`抛出`NullPointerException`后，被`process1()`捕获，然后抛出`IllegalArgumentException()`。

如果在`main()`中捕获`IllegalArgumentException`，我们看看打印的异常栈：

```java
public class Main {
    public static void main(String[] args) {
        try {
            process1();
        } catch (Exception e) {
            e.printStackTrace();
        }
    }

    static void process1() {
        try {
            process2();
        } catch (NullPointerException e) {
            throw new IllegalArgumentException();
        }
    }

    static void process2() {
        throw new NullPointerException();
    }
}
```

打印出的异常栈类似：

```txt
java.lang.IllegalArgumentException
	at com.ln.exception.Main.process1(Main.java:19)
	at com.ln.exception.Main.main(Main.java:9)
```

这说明新的异常丢失了原始异常信息，我们已经看不到原始异常`NullPointerException`的信息了。

为了能追踪到完整的异常栈，在构造异常的时候，把原始的`Exception`实例传进去，新的`Exception`就可以持有原始`Exception`信息。对上述代码改进如下：

```java
public class Main {
    public static void main(String[] args) {
        try {
            process1();
        } catch (Exception e) {
            e.printStackTrace();
        }
    }

    static void process1() {
        try {
            process2();
        } catch (NullPointerException e) {
            throw new IllegalArgumentException(e);
        }
    }

    static void process2() {
        throw new NullPointerException();
    }
}
```

运行上述代码，打印出的异常栈类似：

```txt
java.lang.IllegalArgumentException: java.lang.NullPointerException
    at Main.process1(Main.java:15)
    at Main.main(Main.java:5)
Caused by: java.lang.NullPointerException
    at Main.process2(Main.java:20)
    at Main.process1(Main.java:13)
```

注意到`Caused by: Xxx`，说明捕获的`IllegalArgumentException`并不是造成问题的根源，根源在于`NullPointerException`，是在`Main.process2()`方法抛出的。

在代码中获取原始异常可以使用`Throwable.getCause()`方法。如果返回`null`，说明已经是“根异常”了。

有了完整的异常栈的信息，我们才能快速定位并修复代码的问题。

**捕获到异常并再次抛出时，一定要留住原始异常，否则很难定位第一案发现场！**

如果我们在`try`或者`catch`语句块中抛出异常，`finally`语句是否会执行？例如：

```java
public class Main {
    public static void main(String[] args) {
        try {
            Integer.parseInt("abc");
        } catch (Exception e) {
            System.out.println("catched");
            throw new RuntimeException(e);
        } finally {
            System.out.println("finally");
        }
    }
}
```

上述代码执行结果如下：

```java
catched
finally
Exception in thread "main" java.lang.RuntimeException: java.lang.NumberFormatException: For input string: "abc"
	at com.ln.exception.Main.main(Main.java:12)
Caused by: java.lang.NumberFormatException: For input string: "abc"
	at java.lang.NumberFormatException.forInputString(NumberFormatException.java:65)
	at java.lang.Integer.parseInt(Integer.java:580)
	at java.lang.Integer.parseInt(Integer.java:615)
	at com.ln.exception.Main.main(Main.java:9)

```

第一行打印了`catched`，说明进入了`catch`语句块。第二行打印了`finally`，说明执行了`finally`语句块。

因此，在`catch`中抛出异常，不会影响`finally`的执行。JVM会先执行`finally`，然后抛出异常。

#### 异常屏蔽

如果在执行`finally`语句时抛出异常，那么，`catch`语句的异常还能否继续抛出？例如：

```java
public class Main {
    public static void main(String[] args) {
        try {
            Integer.parseInt("abc");
        } catch (Exception e) {
            System.out.println("catched");
            throw new RuntimeException(e);
        } finally {
            System.out.println("finally");
            throw new IllegalArgumentException();
        }
    }
}
```

执行上述代码，发现异常信息如下：

```
catched
finally
Exception in thread "main" java.lang.IllegalArgumentException
	at com.ln.exception.Main.main(Main.java:15)
```

这说明`finally`抛出异常后，原来在`catch`中准备抛出的异常就“消失”了，因为只能抛出一个异常。没有被抛出的异常称为“被屏蔽”的异常（Suppressed Exception）。

在极少数的情况下，我们需要获知所有的异常。如何保存所有的异常信息？方法是先用`origin`变量保存原始异常，然后调用`Throwable.addSuppressed()`，把原始异常添加进来，最后在`finally`抛出：

```java
public class Main {
    public static void main(String[] args) throws Exception {
        Exception origin = null;
        try {
            System.out.println(Integer.parseInt("abc"));
        } catch (Exception e) {
            origin = e;
            throw e;
        } finally {
            Exception e = new IllegalArgumentException();
            if (origin != null) {
                e.addSuppressed(origin);
            }
            throw e;
        }
    }
}
```

当`catch`和`finally`都抛出了异常时，虽然`catch`的异常被屏蔽了，但是，`finally`抛出的异常仍然包含了它：

```java
Exception in thread "main" java.lang.IllegalArgumentException
	at com.ln.exception.Main.main(Main.java:15)
	Suppressed: java.lang.NumberFormatException: For input string: "abc"
		at java.lang.NumberFormatException.forInputString(NumberFormatException.java:65)
		at java.lang.Integer.parseInt(Integer.java:580)
		at java.lang.Integer.parseInt(Integer.java:615)
		at com.ln.exception.Main.main(Main.java:10)
```

通过`Throwable.getSuppressed()`可以获取所有的`Suppressed Exception`。

绝大多数情况下，在`finally`中不要抛出异常。因此，我们通常不需要关心`Suppressed Exception`。

#### 小结

调用`printStackTrace()`可以打印异常的传播栈，对于调试非常有用；

捕获异常并再次抛出新的异常时，应该持有原始异常信息；

通常不要在`finally`中抛出异常。如果在`finally`中抛出异常，应该原始异常加入到原有异常中。调用方可通过`Throwable.getSuppressed()`获取所有添加的`Suppressed Exception`。

### 自定义异常

Java标准库定义的常用异常包括：

```ascii
Exception
│
├─ RuntimeException
│  │
│  ├─ NullPointerException
│  │
│  ├─ IndexOutOfBoundsException
│  │
│  ├─ SecurityException
│  │
│  └─ IllegalArgumentException
│     │
│     └─ NumberFormatException
│
├─ IOException
│  │
│  ├─ UnsupportedCharsetException
│  │
│  ├─ FileNotFoundException
│  │
│  └─ SocketException
│
├─ ParseException
│
├─ GeneralSecurityException
│
├─ SQLException
│
└─ TimeoutException
```

当我们在代码中需要抛出异常时，尽量使用JDK已定义的异常类型。例如，参数检查不合法，应该抛出`IllegalArgumentException`：

```java
static void process1(int age) {
    if (age <= 0) {
        throw new IllegalArgumentException();
    }
}
```

在一个大型项目中，可以自定义新的异常类型，但是，保持一个合理的异常继承体系是非常重要的。

一个常见的做法是自定义一个`BaseException`作为“根异常”，然后，派生出各种业务类型的异常。

`BaseException`需要从一个适合的`Exception`派生，通常建议从`RuntimeException`派生：

```java
public class BaseException extends RuntimeException {
    
}
```

其他业务类型的异常就可以从`BaseException`派生：

```java
public class UserNotFoundException extends BaseException {
    
}

public class LoginFailedException extends BaseException {
    
}

...
```

自定义的`BaseException`应该提供多个构造方法：

```java
public class BaseException extends RuntimeException {
    public BaseException() {
        super();
    }

    public BaseException(String message, Throwable cause) {
        super(message, cause);
    }

    public BaseException(String message) {
        super(message);
    }

    public BaseException(Throwable cause) {
        super(cause);
    }
}
```

上述构造方法实际上都是原样照抄`RuntimeException`。这样，抛出异常的时候，就可以选择合适的构造方法。通过IDE可以根据父类快速生成子类的构造方法。

#### 小结

抛出异常时，尽量复用JDK已定义的异常类型；

自定义异常体系时，推荐从`RuntimeException`派生“根异常”，再派生出业务异常；

自定义异常时，应该提供多种构造方法。

### NullPointerException

`NullPointerException`即空指针异常，俗称NPE。如果一个对象为`null`，调用其方法或访问其字段就会产生`NullPointerException`，这个异常通常是由JVM抛出的，例如：

```java
public class Main {
    public static void main(String[] args) {
        String s = null;
        System.out.println(s.toLowerCase());
    }
}
```

#### 处理NullPointerException

如果遇到`NullPointerException`，我们应该如何处理？首先，必须明确，`NullPointerException`是一种代码逻辑错误，遇到`NullPointerException`，遵循原则是早暴露，早修复，严禁使用`catch`来隐藏这种编码错误：

```java
// 错误示例: 捕获NullPointerException
try {
    transferMoney(from, to, amount);
} catch (NullPointerException e) {
}
```

好的编码习惯可以极大地降低`NullPointerException`的产生，例如：

成员变量在定义时初始化：

```
public class Person {
    private String name = "";
}
```

使用空字符串`""`而不是默认的`null`可避免很多`NullPointerException`，编写业务逻辑时，用空字符串`""`表示未填写比`null`安全得多。

返回空字符串`""`、空数组而不是`null`：

```java
public String[] readLinesFromFile(String file) {
    if (getFileSize(file) == 0) {
        // 返回空数组而不是null:
        return new String[0];
    }
    ...
}
```

这样可以使得调用方无需检查结果是否为`null`。

如果调用方一定要根据`null`判断，比如返回`null`表示文件不存在，那么考虑返回`Optional<T>`：

```java
public Optional<String> readFromFile(String file) {
    if (!fileExist(file)) {
        return Optional.empty();
    }
    ...
}
```

这样调用方必须通过`Optional.isPresent()`判断是否有结果。

#### 定位NullPointerException

如果产生了`NullPointerException`，例如，调用`a.b.c.x()`时产生了`NullPointerException`，原因可能是：

- `a`是`null`；
- `a.b`是`null`；
- `a.b.c`是`null`；

从Java 14开始，如果产生了`NullPointerException`，JVM可以给出详细的信息告诉我们`null`对象到底是谁。我们来看例子：

```java
public class Main {
    public static void main(String[] args) {
        Person p = new Person();
        System.out.println(p.address.city.toLowerCase());
    }
}

class Person {
    String[] name = new String[2];
    Address address = new Address();
}

class Address {
    String city;
    String street;
    String zipcode;
}
```

可以在`NullPointerException`的详细信息中看到类似`... because "<local1>.address.city" is null`，意思是`city`字段为`null`，这样我们就能快速定位问题所在。

这种增强的`NullPointerException`详细信息是Java 14新增的功能，但默认是关闭的，我们可以给JVM添加一个`-XX:+ShowCodeDetailsInExceptionMessages`参数启用它：

```java
java -XX:+ShowCodeDetailsInExceptionMessages Main.java
```

#### 小结

`NullPointerException`是Java代码常见的逻辑错误，应当早暴露，早修复；

可以启用Java 14的增强异常信息来查看`NullPointerException`的详细错误信息。